#VRML_SIM R2019a utf8
WorldInfo {
}
Viewpoint {
  orientation -0.6931032800836722 0.6931032800836722 0.1980295085953349 0.75
  position 1.2 1.6 2.3
}
TexturedBackground {
}
TexturedBackgroundLight {
}
Floor {
}
Robot {
  translation 0.1 0.22500000000000003 0.1
  children [
    DEF GR_Robot Group {
      children [
        Shape {
          appearance PBRAppearance {
            baseColor 0.9372549019607843 0.1607843137254902 0.1607843137254902
          }
          geometry DEF G_BOX Box {
            size 0.25 0.07 0.1
          }
        }
        Transform {
          translation 0.11 -0.05 0
          children [
            Shape {
              appearance PBRAppearance {
                baseColor 0.4470588235294118 0.6235294117647059 0.8117647058823529
                roughness 1
                metalness 0
              }
              geometry DEF CRY_wheel Sphere {
                radius 0.015
              }
            }
          ]
        }
      ]
    }
    HingeJoint {
      jointParameters HingeJointParameters {
        axis 0 0 1
        anchor -0.05 0 0.06
      }
      device [
        PositionSensor {
          name "position_sensor1"
          resolution 1
        }
        RotationalMotor {
          name "motor_right"
          maxVelocity 52.35
          maxTorque 0
        }
      ]
      endPoint Solid {
        translation -0.050018931518746396 -3.205418028221112e-05 0.059994511580506664
        rotation -0.2801654623273084 -0.6785180070132103 -0.6790586336081345 3.6883309568015745
        children [
          Shape {
            appearance DEF A_W PBRAppearance {
              baseColor 0 0 0
            }
            geometry DEF G_W Cylinder {
              height 0.02
              radius 0.075
            }
          }
        ]
        name "solid(1)"
        boundingObject USE G_W
        physics Physics {
        }
      }
    }
    HingeJoint {
      jointParameters HingeJointParameters {
        axis 0 0 1
        anchor -0.05 0 -0.06
      }
      device [
        RotationalMotor {
          name "motor_left"
          maxVelocity 52.35
          maxTorque 0
        }
      ]
      endPoint Solid {
        translation -0.04999799004042214 1.0347725128983e-05 -0.06000000019718594
        rotation -0.9353081278216833 -0.2500993537570455 -0.25029786111951896 4.646354465627367
        children [
          Shape {
            appearance USE A_W
            geometry USE G_W
          }
        ]
        boundingObject USE G_W
        physics Physics {
        }
      }
    }
    DistanceSensor {
      translation 0.125 0 0
      children [
        Shape {
          appearance PBRAppearance {
            baseColor 0.45098039215686275 0.8235294117647058 0.08627450980392157
          }
          geometry Box {
            size 0.02 0.01 0.01
          }
        }
      ]
      name "distance_sensor"
      lookupTable [
        0 0 0
        0.02 0 0
        5 1023 0
      ]
      resolution 1
    }
  ]
  name "robot(1)"
  boundingObject USE GR_Robot
  physics Physics {
    density -1
    mass 5
  }
  controller "u2_wp"
}
Solid {
  translation 0.5 0.1 0
  children [
    Shape {
      appearance PBRAppearance {
        baseColor 0.807843137254902 0.3607843137254902 0
      }
      geometry DEF G_BOX Box {
        size 0.1 0.2 0.2
      }
    }
  ]
  boundingObject USE G_BOX
  physics Physics {
  }
}
